{"uuid": "e1665d0c-788e-4328-bbda-d4a144c7bd15", "children": ["d3313f34-8d9a-4f85-b57c-11eb47ac8360"], "befores": [{"name": "driver", "status": "broken", "statusDetails": {"message": "urllib3.exceptions.MaxRetryError: HTTPConnectionPool(host='localhost', port=4723): Max retries exceeded with url: /wd/hub/session (Caused by NewConnectionError('<urllib3.connection.HTTPConnection object at 0x7fe9020e7c70>: Failed to establish a new connection: [Errno 61] Connection refused'))\n", "trace": "  File \"/Library/Frameworks/Python.framework/Versions/3.9/lib/python3.9/site-packages/pluggy/callers.py\", line 187, in _multicall\n    res = hook_impl.function(*args)\n  File \"/Library/Frameworks/Python.framework/Versions/3.9/lib/python3.9/site-packages/_pytest/fixtures.py\", line 1126, in pytest_fixture_setup\n    result = call_fixture_func(fixturefunc, request, kwargs)\n  File \"/Library/Frameworks/Python.framework/Versions/3.9/lib/python3.9/site-packages/_pytest/fixtures.py\", line 932, in call_fixture_func\n    fixture_result = fixturefunc(**kwargs)\n  File \"/Users/annakostromina/Desktop/JeansApp/JenasAppium/conftest.py\", line 14, in driver\n    driver = webdriver.Remote('http://localhost:4723/wd/hub',desired_capabilities)\n  File \"/Library/Frameworks/Python.framework/Versions/3.9/lib/python3.9/site-packages/appium/webdriver/webdriver.py\", line 155, in __init__\n    super().__init__(\n  File \"/Library/Frameworks/Python.framework/Versions/3.9/lib/python3.9/site-packages/selenium/webdriver/remote/webdriver.py\", line 157, in __init__\n    self.start_session(capabilities, browser_profile)\n  File \"/Library/Frameworks/Python.framework/Versions/3.9/lib/python3.9/site-packages/appium/webdriver/webdriver.py\", line 225, in start_session\n    response = self.execute(RemoteCommand.NEW_SESSION, parameters)\n  File \"/Library/Frameworks/Python.framework/Versions/3.9/lib/python3.9/site-packages/selenium/webdriver/remote/webdriver.py\", line 319, in execute\n    response = self.command_executor.execute(driver_command, params)\n  File \"/Library/Frameworks/Python.framework/Versions/3.9/lib/python3.9/site-packages/selenium/webdriver/remote/remote_connection.py\", line 374, in execute\n    return self._request(command_info[0], url, body=data)\n  File \"/Library/Frameworks/Python.framework/Versions/3.9/lib/python3.9/site-packages/selenium/webdriver/remote/remote_connection.py\", line 397, in _request\n    resp = self._conn.request(method, url, body=body, headers=headers)\n  File \"/Library/Frameworks/Python.framework/Versions/3.9/lib/python3.9/site-packages/urllib3/request.py\", line 78, in request\n    return self.request_encode_body(\n  File \"/Library/Frameworks/Python.framework/Versions/3.9/lib/python3.9/site-packages/urllib3/request.py\", line 170, in request_encode_body\n    return self.urlopen(method, url, **extra_kw)\n  File \"/Library/Frameworks/Python.framework/Versions/3.9/lib/python3.9/site-packages/urllib3/poolmanager.py\", line 375, in urlopen\n    response = conn.urlopen(method, u.request_uri, **kw)\n  File \"/Library/Frameworks/Python.framework/Versions/3.9/lib/python3.9/site-packages/urllib3/connectionpool.py\", line 783, in urlopen\n    return self.urlopen(\n  File \"/Library/Frameworks/Python.framework/Versions/3.9/lib/python3.9/site-packages/urllib3/connectionpool.py\", line 783, in urlopen\n    return self.urlopen(\n  File \"/Library/Frameworks/Python.framework/Versions/3.9/lib/python3.9/site-packages/urllib3/connectionpool.py\", line 783, in urlopen\n    return self.urlopen(\n  File \"/Library/Frameworks/Python.framework/Versions/3.9/lib/python3.9/site-packages/urllib3/connectionpool.py\", line 755, in urlopen\n    retries = retries.increment(\n  File \"/Library/Frameworks/Python.framework/Versions/3.9/lib/python3.9/site-packages/urllib3/util/retry.py\", line 574, in increment\n    raise MaxRetryError(_pool, url, error or ResponseError(cause))\n"}, "start": 1616094561995, "stop": 1616094562015}], "start": 1616094561995, "stop": 1616094562347}